handling exception
Error: "throw from finally"
#(tests/23-throw-from-catch-with-finally.p:3)       throw "throw from finally"
                                            |.......^
#(tests/23-throw-from-catch-with-finally.p:2) def tryIt() {
                                            |.^
#(tests/23-throw-from-catch-with-finally.p:1) tryIt()
                                            |.^
